Workbook

Sheet Ativos
A1: Ações Brasileiras
A2: Ordem | B2: Ação | C2: Ticker | D2: % do Total | E2: Valor Hoje | F2: Var. (±%) | G2: Total | H2: P. Médio | I2: Qtd. Ações | J2: V. Pago | L2: Montante | M2: A. BRL | N2: FII'S | O2: A. U$D | P2: CRIPTOS | Q2: PROJETA | R2: R. FIXA | S2: TOTAL
A3: 44306 | B3: #VALUE! | C3: {=_FV(B3,"Símbolo do ticker",TRUE)} -> NEOE3 | D3: =G3/$G$13 -> 0.10093353 | E3: {=_FV(B3,"Preço")} -> 16.51 | F3: =(E3-H3)/H3 -> -0.0030193237 | G3: =E3*I3 -> 330.2 | H3: 16.56 | I3: 20 | J3: =I3*H3 -> 331.2 | L3: V. Pago | M3: =J13 -> 3252.56 | N3: =J23 -> 3244.18 | O3: =J36 -> 3028.7627 | P3: =J48 -> 901.58 | Q3: =J64/2 -> 4151.8 | R3: =3250+1286.78 -> 4536.78 | S3: =SUM(M3:R3) -> 19115.663
A4: 44306 | B4: #VALUE! | C4: {=_FV(B4,"Símbolo do ticker",TRUE)} -> PNVL3 | D4: =G4/$G$13 -> 0.10216234 | E4: {=_FV(B4,"Preço")} -> 19.66 | F4: =(E4-H4)/H4 -> 0.021829522 | G4: =E4*I4 -> 334.22 | H4: 19.24 | I4: 17 | J4: =I4*H4 -> 327.08 | L4: V. Atual | M4: =G13 -> 3271.46 | N4: =G23 -> 3253.29 | O4: =G36 -> 3059.1075 | P4: =G48 -> 977.52826 | Q4: =G64/2 -> 4098.73 | R4: =3251.68+1288.83 -> 4540.51 | S4: =SUM(M4:R4) -> 19200.626
A5: 44306 | B5: #VALUE! | C5: {=_FV(B5,"Símbolo do ticker",TRUE)} -> MYPK3 | D5: =G5/$G$13 -> 0.10285316 | E5: {=_FV(B5,"Preço")} -> 14.02 | F5: =(E5-H5)/H5 -> 0.017416546 | G5: =E5*I5 -> 336.48 | H5: 13.78 | I5: 24 | J5: =I5*H5 -> 330.72 | L5: Var. (±%) | M5: =(M4-M3)/M3 -> 0.0058108075 | N5: =(N4-N3)/N3 -> 0.0028081056 | O5: =(O4-O3)/O3 -> 0.010018878 | P5: =(P4-P3)/P3 -> 0.084239068 | Q5: =(Q4-Q3)/Q3 -> -0.012782408 | R5: =(R4-R3)/R3 -> 0.00082216903 | S5: =(S4-S3)/S3 -> 0.0044446831
A6: 44306 | B6: #VALUE! | C6: {=_FV(B6,"Símbolo do ticker",TRUE)} -> MDIA3 | D6: =G6/$G$13 -> 0.090785154 | E6: {=_FV(B6,"Preço")} -> 27 | F6: =(E6-H6)/H6 -> -0.05726257 | G6: =E6*I6 -> 297 | H6: 28.64 | I6: 11 | J6: =I6*H6 -> 315.04 | L6: Var. (BRL) | M6: =M4-M3 -> 18.9 | N6: =N4-N3 -> 9.11 | O6: =O4-O3 -> 30.344804 | P6: =P4-P3 -> 75.948259 | Q6: =Q4-Q3 -> -53.07 | R6: =R4-R3 -> 3.73 | S6: =S4-S3 -> 84.963063
A7: 44306 | B7: #VALUE! | C7: {=_FV(B7,"Símbolo do ticker",TRUE)} -> ITSA4 | D7: =G7/$G$13 -> 0.10172828 | E7: {=_FV(B7,"Preço")} -> 10.4 | F7: =(E7-H7)/H7 -> 0.02060844 | G7: =E7*I7 -> 332.8 | H7: 10.19 | I7: 32 | J7: =I7*H7 -> 326.08
A8: 44306 | B8: #VALUE! | C8: {=_FV(B8,"Símbolo do ticker",TRUE)} -> B3SA3 | D8: =G8/$G$13 -> 0.098304732 | E8: {=_FV(B8,"Preço")} -> 53.6 | F8: =(E8-H8)/H8 -> -0.010705057 | G8: =E8*I8 -> 321.6 | H8: 54.18 | I8: 6 | J8: =I8*H8 -> 325.08
A9: 44306 | B9: #VALUE! | C9: {=_FV(B9,"Símbolo do ticker",TRUE)} -> EGIE3 | D9: =G9/$G$13 -> 0.10163046 | E9: {=_FV(B9,"Preço")} -> 41.56 | F9: =(E9-H9)/H9 -> 0.0016871535 | G9: =E9*I9 -> 332.48 | H9: 41.49 | I9: 8 | J9: =I9*H9 -> 331.92
A10: 44306 | B10: #VALUE! | C10: {=_FV(B10,"Símbolo do ticker",TRUE)} -> BBAS3 | D10: =G10/$G$13 -> 0.10188112 | E10: {=_FV(B10,"Preço")} -> 30.3 | F10: =(E10-H10)/H10 -> 0.010673783 | G10: =E10*I10 -> 333.3 | H10: 29.98 | I10: 11 | J10: =I10*H10 -> 329.78
A11: 44306 | B11: #VALUE! | C11: {=_FV(B11,"Símbolo do ticker",TRUE)} -> VIVT3 | D11: =G11/$G$13 -> 0.091879467 | E11: {=_FV(B11,"Preço")} -> 42.94 | F11: =(E11-H11)/H11 -> -0.019186843 | G11: =E11*I11 -> 300.58 | H11: 43.78 | I11: 7 | J11: =I11*H11 -> 306.46
A12: 44306 | B12: #VALUE! | C12: {=_FV(B12,"Símbolo do ticker",TRUE)} -> JALL3 | D12: =G12/$G$13 -> 0.10784176 | E12: {=_FV(B12,"Preço")} -> 8.82 | F12: =(E12-H12)/H12 -> 0.071688943 | G12: =E12*I12 -> 352.8 | H12: 8.23 | I12: 40 | J12: =I12*H12 -> 329.2
F13: Total | G13: =SUM(G3:G12) -> 3271.46 | I13: Total | J13: =SUM(J3:J12) -> 3252.56
A17: Fundos Imobiliarios
A18: Ordem | B18: Ação | C18: Ticker | D18: % do Total | E18: Valor Hoje | F18: Var. (±%) | G18: Total | H18: P. Médio | I18: Qtd. Ações | J18: V. Pago
A19: 44306 | B19: #VALUE! | C19: {=_FV(B19,"Símbolo do ticker",TRUE)} -> MXRF11 | D19: =G19/$G$23 -> 0.2604133 | E19: {=_FV(B19,"Preço")} -> 10.59 | F19: =(E19-H19)/H19 -> 0.010496183 | G19: =E19*I19 -> 847.2 | H19: 10.48 | I19: 80 | J19: =I19*H19 -> 838.4
A20: 44306 | B20: #VALUE! | C20: {=_FV(B20,"Símbolo do ticker",TRUE)} -> MCCI11 | D20: =G20/$G$23 -> 0.25303616 | E20: {=_FV(B20,"Preço")} -> 102.9 | F20: =(E20-H20)/H20 -> -0.0033898305 | G20: =E20*I20 -> 823.2 | H20: 103.25 | I20: 8 | J20: =I20*H20 -> 826
A21: 44306 | B21: #VALUE! | C21: {=_FV(B21,"Símbolo do ticker",TRUE)} -> RBRP11 | D21: =G21/$G$23 -> 0.24067944 | E21: {=_FV(B21,"Preço")} -> 87 | F21: =(E21-H21)/H21 -> -0.022252192 | G21: =E21*I21 -> 783 | H21: 88.98 | I21: 9 | J21: =I21*H21 -> 800.82
A22: 44306 | B22: #VALUE! | C22: {=_FV(B22,"Símbolo do ticker",TRUE)} -> BTLG11 | D22: =G22/$G$23 -> 0.2458711 | E22: {=_FV(B22,"Preço")} -> 114.27 | F22: =(E22-H22)/H22 -> 0.026869159 | G22: =E22*I22 -> 799.89 | H22: 111.28 | I22: 7 | J22: =I22*H22 -> 778.96
F23: Total | G23: =SUM(G19:G22) -> 3253.29 | I23: Total | J23: =SUM(J19:J22) -> 3244.18
A26: Ações Americanas
A27: Ordem | B27: Ação | C27: Ticker | D27: % do Total | E27: Valor Hoje | F27: Var. (±%) | G27: Total | H27: P. Médio | I27: Qtd. Ações | J27: V. Pago
A28: 44305 | B28: #VALUE! | C28: {=_FV(B28,"Símbolo do ticker",TRUE)} -> AMZN | D28: =G28/$G$35 -> 0.16349801 | E28: {=_FV(B28,"Preço")} -> 3458.5 | F28: =(E28-H28)/H28 -> 0.025247036 | G28: =E28*I28 -> 93.3795 | H28: =J28/I28 -> 3373.3333 | I28: 0.027 | J28: 91.08
A29: 44305 | B29: #VALUE! | C29: {=_FV(B29,"Símbolo do ticker",TRUE)} -> BRK.B | D29: =G29/$G$35 -> 0.16162839 | E29: {=_FV(B29,"Preço")} -> 272.95 | F29: =(E29-H29)/H29 -> 0.013523166 | G29: =E29*I29 -> 92.31169 | H29: =J29/I29 -> 269.3081 | I29: 0.3382 | J29: 91.08
A30: 44305 | B30: #VALUE! | C30: {=_FV(B30,"Símbolo do ticker",TRUE)} -> KO | D30: =G30/$G$35 -> 0.15781376 | E30: {=_FV(B30,"Preço")} -> 53.59 | F30: =(E30-H30)/H30 -> -0.0080010896 | G30: =E30*I30 -> 90.133021 | H30: =J30/I30 -> 54.022237 | I30: 1.6819 | J30: 90.86
A31: 44305 | B31: #VALUE! | C31: {=_FV(B31,"Símbolo do ticker",TRUE)} -> AAPL | D31: =G31/$G$35 -> 0.15834015 | E31: {=_FV(B31,"Preço")} -> 133.58 | F31: =(E31-H31)/H31 -> -0.0061142983 | G31: =E31*I31 -> 90.43366 | H31: =J31/I31 -> 134.40177 | I31: 0.677 | J31: 90.99
A32: 44305 | B32: #VALUE! | C32: {=_FV(B32,"Símbolo do ticker",TRUE)} -> WFC | D32: =G32/$G$35 -> 0.1631967 | E32: {=_FV(B32,"Preço")} -> 45.08 | F32: =(E32-H32)/H32 -> 0.02617426 | G32: =E32*I32 -> 93.207408 | H32: =J32/I32 -> 43.930161 | I32: 2.0676 | J32: 90.83
A33: 44305 | B33: #VALUE! | C33: {=_FV(B33,"Símbolo do ticker",TRUE)} -> MSFT | D33: =G33/$G$35 -> 0.086066348 | E33: {=_FV(B33,"Preço")} -> 254.56 | F33: =(E33-H33)/H33 -> -0.016495878 | G33: =E33*I33 -> 49.155536 | H33: =J33/I33 -> 258.82962 | I33: 0.1931 | J33: 49.98
A34: 44305 | B34: #VALUE! | C34: {=_FV(B34,"Símbolo do ticker",TRUE)} -> GOOGL | D34: =G34/$G$35 -> 0.10945664 | E34: {=_FV(B34,"Preço")} -> 2359.04 | F34: =(E34-H34)/H34 -> 0.030742951 | G34: =E34*I34 -> 62.51456 | H34: =J34/I34 -> 2288.6792 | I34: 0.0265 | J34: 60.65
F35: Total | G35: =SUM(G28:G34) -> 571.13537 | I35: Total | J35: =SUM(J28:J34) -> 565.47
F36: Total | G36: =G35/'Cotações das Moedas'!C2 -> 3059.1075 | I36: Total | J36: =J35/'Cotações das Moedas'!C2 -> 3028.7627
A39: Cripto Moedas
A40: Ordem | B40: Ação | C40: Ticker | D40: % do Total | E40: Valor Hoje | F40: Var. (±%) | G40: Total | H40: P. Médio | I40: Qtd. Ações | J40: V. Pago
A41: 44306 | B41: #VALUE! | C41: BTC | D41: =G41/$G$47 -> 0.1996389 | E41: =VLOOKUP(C41,'Cotação Criptos'!D:E,2,0) -> 54380.6 | F41: =(E41-H41)/H41 -> 0.056087014 | G41: =E41*I41 -> 36.435002 | H41: =J41/I41 -> 51492.537 | I41: 0.00067 | J41: 34.5
A42: 44306 | B42: #VALUE! | C42: XRP | D42: =G42/$G$47 -> 0.2600385 | E42: =VLOOKUP(C42,'Cotação Criptos'!D:E,2,0) -> 1.40199 | F42: =(E42-H42)/H42 -> 0.29813889 | G42: =E42*I42 -> 47.458203 | H42: 1.08 | I42: 33.8506 | J42: =H42*I42 -> 36.558648
A43: 44306 | C43: ADA | D43: =G43/$G$47 -> 0.18355737 | E43: =VLOOKUP(C43,'Cotação Criptos'!D:E,2,0) -> 1.392087 | F43: =(E43-H43)/H43 -> 0.15917134 | G43: =E43*I43 -> 33.500052 | H43: =J43/I43 -> 1.2009329 | I43: 24.064625 | J43: 28.9
A44: 44306 | C44: ETC | D44: =G44/$G$47 -> 0.15212806 | E44: =VLOOKUP(C44,'Cotação Criptos'!D:E,2,0) -> 34.8038 | F44: =(E44-H44)/H44 -> 0.033273517 | G44: =E44*I44 -> 27.764059 | H44: =J44/I44 -> 33.683047 | I44: 0.79773069 | J44: 26.87
A45: 44306 | C45: XMR | D45: =G45/$G$47 -> 0.11385025 | E45: =VLOOKUP(C45,'Cotação Criptos'!D:E,2,0) -> 419.112 | F45: =(E45-H45)/H45 -> 0.10522264 | G45: =E45*I45 -> 20.778186 | H45: =J45/I45 -> 379.21047 | I45: 0.04957669 | J45: 18.8
A46: 44306 | C46: BUSD | D46: =G46/$G$47 -> 0.090786924 | E46: =VLOOKUP(C46,'Cotação Criptos'!D:E,2,0) -> 0.9991 | F46: =(E46-H46)/H46 -> 0.0035750724 | G46: =E46*I46 -> 16.569024 | H46: =J46/I46 -> 0.99554087 | I46: 16.58395 | J46: 16.51
F47: Total | G47: =SUM(G40:G46) -> 182.50453 | I47: Total | J47: =SUM(J40:J46) -> 162.13865
...

Sheet Cotações das Moedas
A1: Símbolo | B1: Nome | C1: Último Preço | D1: Alterar | E1: % Alteração | F1: Variação de 52 semanas | G1: Gráfico Diário
A2: BRLUSD=X | B2: BRL/USD | C2: 0.1867 | D2: -0.0005 | E2: -0.0025
A3: BRLEUR=X | B3: BRL/EUR | C3: 0.1538 | D3: -0.0003 | E3: -0.0021
A4: BRLGBP=X | B4: BRL/GBP | C4: 0.1337 | D4: -0.0004 | E4: -0.0027
A5: BRLJPY=X | B5: BRL/JPY | C5: 20.338 | D5: 0.037 | E5: 0.0018
A6: BRLARS=X | B6: BRL/ARS | C6: 17.4101 | D6: -0.0732 | E6: -0.0042
A7: BRLINR=X | B7: BRL/INR | C7: 13.81 | D7: -0.05 | E7: -0.0036
A8: BRLCAD=X | B8: BRL/CAD | C8: 0.428 | D8: 0 | E8: 0
A9: BRLSEK=X | B9: BRL/SEK | C9: 1.5554 | D9: -0.0015 | E9: -0.001
A10: BRLCNY=X | B10: BRL/CNY | C10: 1.2055 | D10: -0.0045 | E10: -0.0037
A11: BRLAUD=X | B11: BRL/AUD | C11: 0.2394 | D11: -0.0006 | E11: -0.0025
A12: EURUSD=X | B12: EUR/USD | C12: 1.2133 | D12: 0.0004 | E12: 0.0004
A13: JPY=X | B13: USD/JPY | C13: 108.97 | D13: 0.373 | E13: 0.0034
... A38: USDRUB=X | B38: USD/RUB | C38: 74.2437 | D38: -0.1335 | E38: -0.0018

Sheet Cotação Criptos
A1: # | B1: Column1 | C1: Nome | D1: Código | E1: Preço (USD) | F1: Capitalização | G1: Vol. (24h) | H1: Vol. Total | I1: Var (24h) | J1: Var (7d)
A2: 1 | C2: Bitcoin | D2: BTC | E2: 54380.6 | F2: $1,02T | G2: $44,88B | H2: 0.3291 | I2: -0.0087 | J2: -0.0095
A3: 2 | C3: Ethereum | D3: ETH | E3: 2788.24 | F3: $321,74B | G3: $32,55B | H3: 0.2387 | I3: 0.0357 | J3: 0.0782
A4: 3 | C4: Binance Coin | D4: BNB | E4: 601.17 | F4: $91,82B | G4: $5,01B | H4: 0.0367 | I4: 0.0732 | J4: 0.0494
A5: 4 | C5: Ripple | D5: XRP | E5: 1.40199 | F5: $63,76B | G5: $8,10B | H5: 0.0594 | I5: 0.0262 | J5: 0.0537
A6: 5 | C6: Tether | D6: USDT | E6: 1.0006 | F6: $51,02B | G6: $94,11B | H6: 0.6901 | I6: 0.0002 | J6: 0.0002
A7: 6 | C7: Cardano | D7: ADA | E7: 1.392087 | F7: $44,47B | G7: $3,46B | H7: 0.0254 | I7: 0.0733 | J7: 0.1299
A8: 7 | C8: Dogecoin | D8: DOGE | E8: 0.30692 | F8: $39,96B | G8: $7,62B | H8: 0.0559 | I8: -0.0361 | J8: 0.1588
A9: 8 | C9: Polkadot | D9: DOT | E9: 34.266 | F9: $32,05B | G9: $1,54B | H9: 0.0113 | I9: 0.0172 | J9: -0.0315
A10: 9 | C10: Uniswap | D10: UNI | E10: 42.599 | F10: $22,26B | G10: $1,28B | H10: 0.0094 | I10: 0.0172 | J10: 0.1176
A11: 10 | C11: Litecoin | D11: LTC | E11: 260.941 | F11: $17,36B | G11: $3,68B | H11: 0.027 | I11: 0.0204 | J11: -0.082
A12: 11 | C12: Bitcoin Cash | D12: BCH | E12: 900.03 | F12: $16,88B | G12: $3,01B | H12: 0.0221 | I12: 0.017 | J12: -0.0554
A13: 12 | C13: Chainlink | D13: LINK | E13: 37.17 | F13: $15,47B | G13: $1,31B | H13: 0.0096 | I13: 0.0229 | J13: -0.0526
... A101: 100 | C101: IOST | D101: IOST | E101: 0.06265 | F101: $1,03B | G101: $422,10M | H101: 0.0031 | I101: 0.0166 | J101: -0.0001
